<?xml version='1.0'?>

<robot name="myrobot" xmlns:xacro="http://www.ros.org/wiki/xacro">



  <xacro:include filename="$(find mybot_description)/urdf/mybot.gazebo" />
  <xacro:include filename="$(find mybot_description)/urdf/materials.xacro" />
  <xacro:include filename="$(find mybot_description)/urdf/macros.xacro" />


  <link
    name="chassis">
    <inertial>
      <origin
        xyz="-1.40555552583811E-17 0.0529171236151679 0.00391266405428065"
        rpy="0 0 0" />
      <mass
        value="21.1825200418427" />
      <inertia
        ixx="0"
        ixy="0"
        ixz="0"
        iyy="0"
        iyz="0"
        izz="0" />
    </inertial>
    <visual>
      <origin
        xyz="0 0 0"
        rpy="0 0 0" />
      <geometry>
        <mesh
          filename="package://mybot_description/meshes/chassis.STL" />
      </geometry>
      <material
        name="">
        <color
          rgba="0 1 0 1" />
      </material>
    </visual>
    <collision>
      <origin
        xyz="0 0 0"
        rpy="0 0 0" />
      <geometry>
        <mesh
          filename="package://mybot_description/meshes/chassis.STL" />
      </geometry>
    </collision>
  </link>
  <link
    name="right_wheel">
    <inertial>
      <origin
        xyz="0 6.9389E-18 -0.02"
        rpy="0 0 0" />
      <mass
        value="1.8586" />
      <inertia
        ixx="0"
        ixy="0"
        ixz="0"
        iyy="0"
        iyz="0"
        izz="0" />
    </inertial>
    <visual>
      <origin
        xyz="0 0 0"
        rpy="0 0 0" />
      <geometry>
        <mesh
          filename="package://mybot_description/meshes/right_wheel.STL" />
      </geometry>
      <material
        name="">
        <color
          rgba="0.79216 0.81961 0.93333 1" />
      </material>
    </visual>
    <collision>
      <origin
        xyz="0 0 0"
        rpy="0 0 0" />
      <geometry>
        <mesh
          filename="package://mybot_description/meshes/right_wheel.STL" />
      </geometry>
    </collision>
  </link>
  <joint
    name="right_wheel_hinge"
    type="continuous">
    <origin
      xyz="-0.20139 -0.154 0.0525"
      rpy="1.5708 6.123E-17 1.5708" />
    <parent
      link="chassis" />
    <child
      link="right_wheel" />
    <axis
      xyz="0 0 1" />
  </joint>
  <link
    name="left_wheel">
    <inertial>
      <origin
        xyz="0 6.9389E-18 -0.02"
        rpy="0 0 0" />
      <mass
        value="1.8586" />
      <inertia
        ixx="0"
        ixy="0"
        ixz="0"
        iyy="0"
        iyz="0"
        izz="0" />
    </inertial>
    <visual>
      <origin
        xyz="0 0 0"
        rpy="0 0 0" />
      <geometry>
        <mesh
          filename="package://mybot_description/meshes/left_wheel.STL" />
      </geometry>
      <material
        name="">
        <color
          rgba="0.79216 0.81961 0.93333 1" />
      </material>
    </visual>
    <collision>
      <origin
        xyz="0 0 0"
        rpy="0 0 0" />
      <geometry>
        <mesh
          filename="package://mybot_description/meshes/left_wheel.STL" />
      </geometry>
    </collision>
  </link>
  <joint
    name="left_wheel_hinge"
    type="continuous">
    <origin
      xyz="0.20139 -0.154 0.0525"
      rpy="1.5708 -0.54129 -1.5708" />
    <parent
      link="chassis" />
    <child
      link="left_wheel" />
    <axis
      xyz="0 0 -1" />
  </joint>
  <link
    name="caster">
    <inertial>
      <origin
        xyz="-0.03316 -0.021428 0.0014432"
        rpy="0 0 0" />
      <mass
        value="2.6779" />
      <inertia
        ixx="0.0047707"
        ixy="0.0023924"
        ixz="3.8788E-05"
        iyy="0.001833"
        iyz="-9.8371E-05"
        izz="0.0056203" />
    </inertial>
    <visual>
      <origin
        xyz="0 0 0"
        rpy="0 0 0" />
      <geometry>
        <mesh
          filename="package://mybot_description/meshes/caster.STL" />
      </geometry>
      <material
        name="">
        <color
          rgba="0.75294 0.75294 0.75294 1" />
      </material>
    </visual>
    <collision>
      <origin
        xyz="0 0 0"
        rpy="0 0 0" />
      <geometry>
        <mesh
          filename="package://mybot_description/meshes/caster.STL" />
      </geometry>
    </collision>
  </link>
  <joint
    name="caster_hinge"
    type="continuous">
    <origin
      xyz="-0.00439 0.304 0"
      rpy="-1.5708 -4.7843E-17 -1.4236" />
    <parent
      link="chassis" />
    <child
      link="caster" />
    <axis
      xyz="0 -1 0" />
  </joint>
  <link
    name="caster_wheel">
    <inertial>
      <origin
        xyz="-5.4075E-05 -1.2199E-05 8.0768E-09"
        rpy="0 0 0" />
      <mass
        value="3.9193" />
      <inertia
        ixx="0"
        ixy="0"
        ixz="0"
        iyy="0"
        iyz="0"
        izz="0" />
    </inertial>
    <visual>
      <origin
        xyz="0 0 0"
        rpy="0 0 0" />
      <geometry>
        <mesh
          filename="package://mybot_description/meshes/caster_wheel.STL" />
      </geometry>
      <material
        name="">
        <color
          rgba="1 0.68627 0.11765 1" />
      </material>
    </visual>
    <collision>
      <origin
        xyz="0 0 0"
        rpy="0 0 0" />
      <geometry>
        <mesh
          filename="package://mybot_description/meshes/caster_wheel.STL" />
      </geometry>
    </collision>
  </link>
  <joint
    name="caster_wheel_hinge"
    type="continuous">
    <origin
      xyz="-0.05126 0.01175 0.002409"
      rpy="-3.1376 -0.034066 3.0259" />
    <parent
      link="caster" />
    <child
      link="caster_wheel" />
    <axis
      xyz="0 0 0" />
  </joint>
</robot>


